Workbook

Sheet README
A1: Kenya Petroleum Economic Model (companion to the Market Outlook 2026-2035)
A3: How it works: yellow cells with blue text are inputs (sheet Assumptions and the project inputs on Project_Economics). Everything else is a formula.
A4: Change the scenario selector (Assumptions!C3: 1 = Low-demand, 2 = Baseline, 3 = High-demand) and the Scenarios, Supply_Security, LPG_Storage and Dashboard sheets update.
A5: Sheets: Assumptions | Demand_Data | Prices | Scenarios | Supply_Security | LPG_Storage | Project_Economics | Sensitivity (static results from the Python pipeline) | Dashboard
A6: Data: LeadAfrik extract of KNBS Leading Economic Indicators, with the product columns RELABELLED after reconciliation to EPRA PDP 2024 and KNBS 2025 (see Data Quality Report). Jet fuel* and Fuel oil/other* identities are probable, not confirmed.
A7: Scenario growth rates: EPRA Petroleum Development Plan 2025-2029. Price shocks, 2030-35 fade, LPG/kerosene/jet elasticities and all South Lokichar costs and fiscal terms are the author's ASSUMPTIONS.
A8: South Lokichar: illustrative public-information model; NOT official or confidential project economics.
A9: Sensitivity sheet values are static outputs of the Python model (they include break-even solves that Excel cannot do without Goal Seek). The Project_Economics sheet reproduces the base case live.

Sheet Dashboard
A1: KENYA PETROLEUM - DASHBOARD
A2: =Assumptions!D3 -> Baseline
A4: Total demand 2025 (kt) | B4: =Scenarios!I5 -> 5712.48
A5: Total demand 2026 (kt) | B5: =Scenarios!I6 -> 5803.5084
A6: Total demand 2030 (kt) | B6: =Scenarios!I10 -> 6305.6954
A7: Total demand 2035 (kt) | B7: =Scenarios!I15 -> 7157.319
A8: CAGR 2025-35 | B8: =Scenarios!I17 -> 0.022804354
A9: Diesel 2030 (kt) | B9: =Scenarios!B10 -> 2574.4346
A10: Petrol 2030 (kt) | B10: =Scenarios!C10 -> 1872.6445
A11: LPG 2030 (kt) | B11: =Scenarios!D10 -> 647.75862
A12: LPG storage headroom 2030 (kt) | B12: =LPG_Storage!E9 -> -13.986588
A13: LPG storage headroom 2026 (kt) | B13: =LPG_Storage!E5 -> -0.95509054
A14: Diesel shortfall vs standard (ML) | B14: =Supply_Security!D10 -> 86.684348
A15: Petrol shortfall vs standard (ML) | B15: =Supply_Security!D11 -> 88.241614
A16: Project NPV10, US$ m | B16: =Project_Economics!B58 -> 1550.5055
A17: Project IRR | B17: =Project_Economics!B59 -> 0.14946595
A18: Government NPV10, US$ m | B18: =Project_Economics!B60 -> 2812.5138
A19: Contractor NPV10, US$ m | B19: =Project_Economics!B62 -> -1262.0083

Sheet Assumptions
A1: ASSUMPTIONS (yellow = input)
A3: Scenario selector (1=Low-demand, 2=Baseline, 3=High-demand) | B3: Selected | C3: 2 | D3: =CHOOSE(C3,"Low-demand","Baseline","High-demand") -> Baseline
A5: Underlying growth 2025-29, % per year | C5: Low (pessimistic) | D5: Baseline | E5: High (optimistic) | F5: Selected / source
A6: Diesel (AGO) | C6: 2.74 | D6: 3.52 | E6: 4.28 | F6: =INDEX(C6:E6,$C$3) -> 3.52
A7: Petrol (PMS) | C7: 2.97 | D7: 3.35 | E7: 4.08 | F7: =INDEX(C7:E7,$C$3) -> 3.35
A8: LPG | C8: 6.34 | D8: 7.26 | E8: 8.82 | F8: =INDEX(C8:E8,$C$3) -> 7.26
A9: Jet fuel* | C9: 1.7 | D9: 1.87 | E9: 2.17 | F9: =INDEX(C9:E9,$C$3) -> 1.87
A10: Kerosene (IK) | C10: -5.29 | D10: -4.57 | E10: -3.86 | F10: =INDEX(C10:E10,$C$3) -> -4.57
A11: Source: EPRA Petroleum Development Plan 2025-2029 (Section 4).
A12: 2026 average pump-price rise vs 2025, % | C12: Low-demand | D12: Baseline | E12: High-demand | F12: Selected
A13: Diesel (AGO) | C13: 30 | D13: 20 | E13: 10 | F13: =INDEX(C13:E13,$C$3) -> 20
A14: Petrol (PMS) | C14: 22 | D14: 15 | E14: 8 | F14: =INDEX(C14:E14,$C$3) -> 15
A15: LPG | C15: 20 | D15: 10 | E15: 5 | F15: =INDEX(C15:E15,$C$3) -> 10
A16: Jet fuel* | C16: 0 | D16: 0 | E16: 0 | F16: =INDEX(C16:E16,$C$3) -> 0
A17: Kerosene (IK) | C17: 30 | D17: 20 | E17: 10 | F17: =INDEX(C17:E17,$C$3) -> 20
A18: Author assumptions informed by Mar-Sep 2026 EPRA reviews (Nairobi diesel +30.8%, petrol +20.1% Mar-cycle to Sep-cycle).
A19: Price elasticity of demand | C19: Short-run | D19: Long-run | F19: Source
A20: Diesel (AGO) | C20: -0.185 | D20: -0.57 | F20: PDP-implied
A21: Petrol (PMS) | C21: -0.096 | D21: -0.259 | F21: PDP-implied
A22: LPG | C22: -0.15 | D22: -0.3 | F22: Assumption
A23: Jet fuel* | C23: 0 | D23: 0 | F23: Assumption
A24: Kerosene (IK) | C24: -0.2 | D24: -0.5 | F24: Assumption
A26: 2030-35 growth fade factor (x 2025-29 rate) | C26: 0.8 | F26: Assumption
A27: Exchange rate, KSh per USD | C27: 129.2 | F27: Assumption (flat)
A28: Fuel oil growth to 2027, % per year | C28: 4.68 | F28: EPRA PDP
A29: Fuel oil growth after 2027, % per year | C29: -3.19 | F29: EPRA PDP
A30: Stock-cover standard, days | C30: 30 | F30: EPRA PDP (15 operational + 15 strategic)
A31: Installed LPG storage, kt (Mar-2025) | C31: 44.43 | F31: EPRA PDP
A32: Additional LPG storage commissioned, kt (e.g. Lake Gas 10) | C32: 0 | F32: Input; status unverified
A33: ML per kt: diesel | C33: 1.1890044 | F33: PDP-implied
A34: ML per kt: petrol | C34: 1.3880016 | F34: PDP-implied
A35: ML per kt: jet | C35: 1.2710626 | F35: PDP-implied
A36: ML per kt: kerosene | C36: 1.2714286 | F36: PDP-implied

Sheet Demand_Data
A1: Month | B1: Year | C1: Diesel (AGO) | D1: Petrol (PMS) | E1: LPG | F1: Jet fuel* | G1: Fuel oil/other* | H1: Kerosene (IK) | I1: Avgas | J1: Total
A2: 45292 | B2: 2024 | C2: 177.1 | D2: 123.17 | E2: 32.45 | F2: 60.91 | G2: 17.38 | H2: 3.15 | I2: 0.06 | J2: 414.22
A3: 45323 | B3: 2024 | C3: 178.65 | D3: 114.16 | E3: 28.07 | F3: 59.99 | G3: 18.73 | H3: 2.83 | I3: 0.11 | J3: 402.54
A4: 45352 | B4: 2024 | C4: 191.86 | D4: 120.07 | E4: 33.66 | F4: 57.55 | G4: 14.15 | H4: 2.51 | I4: 0.06 | J4: 419.86
A5: 45383 | B5: 2024 | C5: 170.42 | D5: 113.73 | E5: 31.8 | F5: 59.57 | G5: 22.64 | H5: 3.36 | I5: 0.04 | J5: 401.56
A6: 45413 | B6: 2024 | C6: 182.42 | D6: 117.91 | E6: 36.17 | F6: 59.8 | G6: 24.97 | H6: 3.22 | I6: 0.08 | J6: 424.57
A7: 45444 | B7: 2024 | C7: 165.78 | D7: 106.84 | E7: 33.3 | F7: 60.61 | G7: 13.07 | H7: 3.11 | I7: 0.07 | J7: 382.78
A8: 45474 | B8: 2024 | C8: 192.18 | D8: 126.09 | E8: 37.35 | F8: 64.78 | G8: 21.63 | H8: 3.39 | I8: 0.09 | J8: 445.51
A9: 45505 | B9: 2024 | C9: 195.49 | D9: 128.32 | E9: 38.27 | F9: 57.84 | G9: 28.88 | H9: 3.44 | I9: 0.07 | J9: 452.31
A10: 45536 | B10: 2024 | C10: 185.08 | D10: 123.68 | E10: 33.83 | F10: 61.85 | G10: 17.85 | H10: 2.88 | I10: 0.08 | J10: 425.25
A11: 45566 | B11: 2024 | C11: 195.58 | D11: 132.47 | E11: 36.44 | F11: 62.35 | G11: 31.74 | H11: 3.25 | I11: 0.1 | J11: 461.93
A12: 45597 | B12: 2024 | C12: 180 | D12: 121.89 | E12: 36.05 | F12: 63.64 | G12: 15.64 | H12: 3.21 | I12: 0.19 | J12: 420.62
A13: 45627 | B13: 2024 | C13: 179.04 | D13: 144.36 | E13: 37.49 | F13: 63.45 | G13: 23.43 | H13: 2.77 | I13: 0.12 | J13: 450.66
... A27: 46054 | B27: 2026 | C27: 202.46 | D27: 137.6 | E27: 36.48 | F27: 54.57 | G27: 22.51 | H27: 4.16 | I27: 0.11 | J27: 457.89
A28: 46082 | B28: 2026
A31: Annual totals (kt) - complete years only
A32: 2024 | C32: =SUMIFS(C2:C28,$B$2:$B$28,$A32) -> 2193.6 | D32: =SUMIFS(D2:D28,$B$2:$B$28,$A32) -> 1472.69 | E32: =SUMIFS(E2:E28,$B$2:$B$28,$A32) -> 414.88 | F32: =SUMIFS(F2:F28,$B$2:$B$28,$A32) -> 732.34 | G32: =SUMIFS(G2:G28,$B$2:$B$28,$A32) -> 250.11 | H32: =SUMIFS(H2:H28,$B$2:$B$28,$A32) -> 37.12 | I32: =SUMIFS(I2:I28,$B$2:$B$28,$A32) -> 1.07 | J32: =SUMIFS(J2:J28,$B$2:$B$28,$A32) -> 5101.81
A33: 2025 | C33: =SUMIFS(C2:C28,$B$2:$B$28,$A33) -> 2419.12 | D33: =SUMIFS(D2:D28,$B$2:$B$28,$A33) -> 1657.48 | E33: =SUMIFS(E2:E28,$B$2:$B$28,$A33) -> 475.95 | F33: =SUMIFS(F2:F28,$B$2:$B$28,$A33) -> 701.34 | G33: =SUMIFS(G2:G28,$B$2:$B$28,$A33) -> 413.26 | H33: =SUMIFS(H2:H28,$B$2:$B$28,$A33) -> 44.12 | I33: =SUMIFS(I2:I28,$B$2:$B$28,$A33) -> 1.21 | J33: =SUMIFS(J2:J28,$B$2:$B$28,$A33) -> 5712.48
A34: Growth 2025/24 | C34: =C33/C32-1 -> 0.10280817 | D34: =D33/D32-1 -> 0.12547787 | E34: =E33/E32-1 -> 0.14719919 | F34: =F33/F32-1 -> -0.042330065 | G34: =G33/G32-1 -> 0.65231298 | H34: =H33/H32-1 -> 0.18857759 | I34: =I33/I32-1 -> 0.13084112 | J34: =J33/J32-1 -> 0.11969674
A35: Share 2025 | C35: =C33/$J33 -> 0.42347982 | D35: =D33/$J33 -> 0.29015069 | E35: =E33/$J33 -> 0.083317578 | F35: =F33/$J33 -> 0.1227733 | G35: =G33/$J33 -> 0.072343361 | H35: =H33/$J33 -> 0.0077234406 | I35: =I33/$J33 -> 0.00021181693 | J35: =J33/$J33 -> 1

Sheet Prices
A1: Month | B1: Charcoal | C1: Illuminating Kerosene | D1: L.P.G | E1: Light Diesel Oil | F1: Motor Gasoline Premium
A2: 45658 | B2: 86.22 | C2: 152.18 | D2: 3122.16 | E2: 167.84 | F2: 177.25
A3: 45689 | B3: 86.51 | C3: 152.18 | D3: 3139.65 | E3: 167.84 | F3: 177.25
A4: 45717 | B4: 86.64 | C4: 152.18 | D4: 3146.03 | E4: 167.84 | F4: 177.25
A5: 45748 | B5: 86.72 | C5: 149.78 | D5: 3156.19 | E5: 165.64 | F5: 175.3
A6: 45778 | B6: 88.01 | C6: 149.78 | D6: 3141.3 | E6: 165.64 | F6: 175.3
A7: 45809 | B7: 88.89 | C7: 147.92 | D7: 3134.91 | E7: 163.89 | F7: 178.19
A8: 45839 | B8: 89.84 | C8: 157.76 | D8: 3146.58 | E8: 172.75 | F8: 187.37
A9: 45870 | B9: 89.83 | C9: 156.76 | D9: 3158.35 | E9: 172.75 | F9: 186.37
A10: 45901 | B10: 92.87 | C10: 155.96 | D10: 3151.65 | E10: 172.64 | F10: 185.59
A11: 45931 | B11: 92.78 | C11: 155.96 | D11: 3133.49 | E11: 172.64 | F11: 185.59
A12: 45962 | B12: 92.91 | C12: 155.96 | D12: 3132.93 | E12: 172.64 | F12: 185.59
A13: 45992 | B13: 93.31 | C13: 155.96 | D13: 3145.9 | E13: 172.64 | F13: 185.59
... A16: 46082 | B16: 95.45 | C16: 153.96 | D16: 3132.34 | E16: 167.72 | F16: 179.35
A18: Change Jan-25 to Mar-26 | B18: =B16/B2-1 -> 0.10705173 | C18: =C16/C2-1 -> 0.011696675 | D18: =D16/D2-1 -> 0.0032605632 | E18: =E16/E2-1 -> -0.00071496663 | F18: =F16/F2-1 -> 0.011847673
A19: CV | B19: =STDEV(B2:B16)/AVERAGE(B2:B16) -> 0.035852517 | C19: =STDEV(C2:C16)/AVERAGE(C2:C16) -> 0.018976085 | D19: =STDEV(D2:D16)/AVERAGE(D2:D16) -> 0.0031621023 | E19: =STDEV(E2:E16)/AVERAGE(E2:E16) -> 0.018727154 | F19: =STDEV(F2:F16)/AVERAGE(F2:F16) -> 0.024666635
A21: Note: national averages to Mar-2026. 2026 Nairobi maxima after the Gulf-war shock are in the report (Diesel 242.92 in May-26; 217.86 in Sep-26).

Sheet Scenarios
A1: Demand projection 2025-2035 (kt) - driven by the scenario selector
A2: =Assumptions!D3 -> Baseline
A4: Year | B4: Diesel (AGO) | C4: Petrol (PMS) | D4: LPG | E4: Jet fuel* | F4: Kerosene (IK) | G4: Fuel oil/other* | H4: Avgas | I4: Total | J4: YoY total
A5: 2025 | B5: =Demand_Data!C33 -> 2419.12 | C5: =Demand_Data!D33 -> 1657.48 | D5: =Demand_Data!E33 -> 475.95 | E5: =Demand_Data!F33 -> 701.34 | F5: =Demand_Data!H33 -> 44.12 | G5: =Demand_Data!G33 -> 413.26 | H5: =Demand_Data!I33 -> 1.21 | I5: =SUM(B5:H5) -> 5712.48
A6: 2026 | B6: =B5*EXP(LN(1+Assumptions!$F$6*IF($A6<=2029,1,Assumptions!$C$26)/100)+IF($A6=2026,Assumptions!$C$20*LN(1+Assumptions!$F$13/100),IF(OR($A6=2027,$A6=2028),(Assumptions!$D$20-Assumptions!$C$20)*LN(1+Assumptions!$F$13/100)/2,0))) -> 2421.2138 | C6: =C5*EXP(LN(1+Assumptions!$F$7*IF($A6<=2029,1,Assumptions!$C$26)/100)+IF($A6=2026,Assumptions!$C$21*LN(1+Assumptions!$F$14/100),IF(OR($A6=2027,$A6=2028),(Assumptions!$D$21-Assumptions!$C$21)*LN(1+Assumptions!$F$14/100)/2,0))) -> 1690.1754 | D6: =D5*EXP(LN(1+Assumptions!$F$8*IF($A6<=2029,1,Assumptions!$C$26)/100)+IF($A6=2026,Assumptions!$C$22*LN(1+Assumptions!$F$15/100),IF(OR($A6=2027,$A6=2028),(Assumptions!$D$22-Assumptions!$C$22)*LN(1+Assumptions!$F$15/100)/2,0))) -> 503.25746 | E6: =E5*EXP(LN(1+Assumptions!$F$9*IF($A6<=2029,1,Assumptions!$C$26)/100)+IF($A6=2026,Assumptions!$C$23*LN(1+Assumptions!$F$16/100),IF(OR($A6=2027,$A6=2028),(Assumptions!$D$23-Assumptions!$C$23)*LN(1+Assumptions!$F$16/100)/2,0))) -> 714.45506 | F6: =F5*EXP(LN(1+Assumptions!$F$10*IF($A6<=2029,1,Assumptions!$C$26)/100)+IF($A6=2026,Assumptions!$C$24*LN(1+Assumptions!$F$17/100),IF(OR($A6=2027,$A6=2028),(Assumptions!$D$24-Assumptions!$C$24)*LN(1+Assumptions!$F$17/100)/2,0))) -> 40.596087 | G6: =G5*(1+IF($A6<=2027,Assumptions!$C$28,Assumptions!$C$29)/100) -> 432.60057 | H6: =H5 -> 1.21 | I6: =SUM(B6:H6) -> 5803.5084 | J6: =I6/I5-1 -> 0.015935011
A7: 2027 | B7: =B6*EXP(LN(1+Assumptions!$F$6*IF($A7<=2029,1,Assumptions!$C$26)/100)+IF($A7=2026,Assumptions!$C$20*LN(1+Assumptions!$F$13/100),IF(OR($A7=2027,$A7=2028),(Assumptions!$D$20-Assumptions!$C$20)*LN(1+Assumptions!$F$13/100)/2,0))) -> 2419.9981 | C7: =C6*EXP(LN(1+Assumptions!$F$7*IF($A7<=2029,1,Assumptions!$C$26)/100)+IF($A7=2026,Assumptions!$C$21*LN(1+Assumptions!$F$14/100),IF(OR($A7=2027,$A7=2028),(Assumptions!$D$21-Assumptions!$C$21)*LN(1+Assumptions!$F$14/100)/2,0))) -> 1727.0121 | D7: =D6*EXP(LN(1+Assumptions!$F$8*IF($A7<=2029,1,Assumptions!$C$26)/100)+IF($A7=2026,Assumptions!$C$22*LN(1+Assumptions!$F$15/100),IF(OR($A7=2027,$A7=2028),(Assumptions!$D$22-Assumptions!$C$22)*LN(1+Assumptions!$F$15/100)/2,0))) -> 535.94912 | E7: =E6*EXP(LN(1+Assumptions!$F$9*IF($A7<=2029,1,Assumptions!$C$26)/100)+IF($A7=2026,Assumptions!$C$23*LN(1+Assumptions!$F$16/100),IF(OR($A7=2027,$A7=2028),(Assumptions!$D$23-Assumptions!$C$23)*LN(1+Assumptions!$F$16/100)/2,0))) -> 727.81537 | F7: =F6*EXP(LN(1+Assumptions!$F$10*IF($A7<=2029,1,Assumptions!$C$26)/100)+IF($A7=2026,Assumptions!$C$24*LN(1+Assumptions!$F$17/100),IF(OR($A7=2027,$A7=2028),(Assumptions!$D$24-Assumptions!$C$24)*LN(1+Assumptions!$F$17/100)/2,0))) -> 37.695709 | G7: =G6*(1+IF($A7<=2027,Assumptions!$C$28,Assumptions!$C$29)/100) -> 452.84627 | H7: =H6 -> 1.21 | I7: =SUM(B7:H7) -> 5902.5267 | J7: =I7/I6-1 -> 0.017061791
A8: 2028 | B8: =B7*EXP(LN(1+Assumptions!$F$6*IF($A8<=2029,1,Assumptions!$C$26)/100)+IF($A8=2026,Assumptions!$C$20*LN(1+Assumptions!$F$13/100),IF(OR($A8=2027,$A8=2028),(Assumptions!$D$20-Assumptions!$C$20)*LN(1+Assumptions!$F$13/100)/2,0))) -> 2418.7829 | C8: =C7*EXP(LN(1+Assumptions!$F$7*IF($A8<=2029,1,Assumptions!$C$26)/100)+IF($A8=2026,Assumptions!$C$21*LN(1+Assumptions!$F$14/100),IF(OR($A8=2027,$A8=2028),(Assumptions!$D$21-Assumptions!$C$21)*LN(1+Assumptions!$F$14/100)/2,0))) -> 1764.6517 | D8: =D7*EXP(LN(1+Assumptions!$F$8*IF($A8<=2029,1,Assumptions!$C$26)/100)+IF($A8=2026,Assumptions!$C$22*LN(1+Assumptions!$F$15/100),IF(OR($A8=2027,$A8=2028),(Assumptions!$D$22-Assumptions!$C$22)*LN(1+Assumptions!$F$15/100)/2,0))) -> 570.76443 | E8: =E7*EXP(LN(1+Assumptions!$F$9*IF($A8<=2029,1,Assumptions!$C$26)/100)+IF($A8=2026,Assumptions!$C$23*LN(1+Assumptions!$F$16/100),IF(OR($A8=2027,$A8=2028),(Assumptions!$D$23-Assumptions!$C$23)*LN(1+Assumptions!$F$16/100)/2,0))) -> 741.42551 | F8: =F7*EXP(LN(1+Assumptions!$F$10*IF($A8<=2029,1,Assumptions!$C$26)/100)+IF($A8=2026,Assumptions!$C$24*LN(1+Assumptions!$F$17/100),IF(OR($A8=2027,$A8=2028),(Assumptions!$D$24-Assumptions!$C$24)*LN(1+Assumptions!$F$17/100)/2,0))) -> 35.002547 | G8: =G7*(1+IF($A8<=2027,Assumptions!$C$28,Assumptions!$C$29)/100) -> 438.40048 | H8: =H7 -> 1.21 | I8: =SUM(B8:H8) -> 5970.2376 | J8: =I8/I7-1 -> 0.011471512
A9: 2029 | B9: =B8*EXP(LN(1+Assumptions!$F$6*IF($A9<=2029,1,Assumptions!$C$26)/100)+IF($A9=2026,Assumptions!$C$20*LN(1+Assumptions!$F$13/100),IF(OR($A9=2027,$A9=2028),(Assumptions!$D$20-Assumptions!$C$20)*LN(1+Assumptions!$F$13/100)/2,0))) -> 2503.9241 | C9: =C8*EXP(LN(1+Assumptions!$F$7*IF($A9<=2029,1,Assumptions!$C$26)/100)+IF($A9=2026,Assumptions!$C$21*LN(1+Assumptions!$F$14/100),IF(OR($A9=2027,$A9=2028),(Assumptions!$D$21-Assumptions!$C$21)*LN(1+Assumptions!$F$14/100)/2,0))) -> 1823.7675 | D9: =D8*EXP(LN(1+Assumptions!$F$8*IF($A9<=2029,1,Assumptions!$C$26)/100)+IF($A9=2026,Assumptions!$C$22*LN(1+Assumptions!$F$15/100),IF(OR($A9=2027,$A9=2028),(Assumptions!$D$22-Assumptions!$C$22)*LN(1+Assumptions!$F$15/100)/2,0))) -> 612.20193 | E9: =E8*EXP(LN(1+Assumptions!$F$9*IF($A9<=2029,1,Assumptions!$C$26)/100)+IF($A9=2026,Assumptions!$C$23*LN(1+Assumptions!$F$16/100),IF(OR($A9=2027,$A9=2028),(Assumptions!$D$23-Assumptions!$C$23)*LN(1+Assumptions!$F$16/100)/2,0))) -> 755.29017 | F9: =F8*EXP(LN(1+Assumptions!$F$10*IF($A9<=2029,1,Assumptions!$C$26)/100)+IF($A9=2026,Assumptions!$C$24*LN(1+Assumptions!$F$17/100),IF(OR($A9=2027,$A9=2028),(Assumptions!$D$24-Assumptions!$C$24)*LN(1+Assumptions!$F$17/100)/2,0))) -> 33.402931 | G9: =G8*(1+IF($A9<=2027,Assumptions!$C$28,Assumptions!$C$29)/100) -> 424.4155 | H9: =H8 -> 1.21 | I9: =SUM(B9:H9) -> 6154.2121 | J9: =I9/I8-1 -> 0.030815282
A10: 2030 | B10: =B9*EXP(LN(1+Assumptions!$F$6*IF($A10<=2029,1,Assumptions!$C$26)/100)+IF($A10=2026,Assumptions!$C$20*LN(1+Assumptions!$F$13/100),IF(OR($A10=2027,$A10=2028),(Assumptions!$D$20-Assumptions!$C$20)*LN(1+Assumptions!$F$13/100)/2,0))) -> 2574.4346 | C10: =C9*EXP(LN(1+Assumptions!$F$7*IF($A10<=2029,1,Assumptions!$C$26)/100)+IF($A10=2026,Assumptions!$C$21*LN(1+Assumptions!$F$14/100),IF(OR($A10=2027,$A10=2028),(Assumptions!$D$21-Assumptions!$C$21)*LN(1+Assumptions!$F$14/100)/2,0))) -> 1872.6445 | D10: =D9*EXP(LN(1+Assumptions!$F$8*IF($A10<=2029,1,Assumptions!$C$26)/100)+IF($A10=2026,Assumptions!$C$22*LN(1+Assumptions!$F$15/100),IF(OR($A10=2027,$A10=2028),(Assumptions!$D$22-Assumptions!$C$22)*LN(1+Assumptions!$F$15/100)/2,0))) -> 647.75862 | E10: =E9*EXP(LN(1+Assumptions!$F$9*IF($A10<=2029,1,Assumptions!$C$26)/100)+IF($A10=2026,Assumptions!$C$23*LN(1+Assumptions!$F$16/100),IF(OR($A10=2027,$A10=2028),(Assumptions!$D$23-Assumptions!$C$23)*LN(1+Assumptions!$F$16/100)/2,0))) -> 766.58931 | F10: =F9*EXP(LN(1+Assumptions!$F$10*IF($A10<=2029,1,Assumptions!$C$26)/100)+IF($A10=2026,Assumptions!$C$24*LN(1+Assumptions!$F$17/100),IF(OR($A10=2027,$A10=2028),(Assumptions!$D$24-Assumptions!$C$24)*LN(1+Assumptions!$F$17/100)/2,0))) -> 32.18172 | G10: =G9*(1+IF($A10<=2027,Assumptions!$C$28,Assumptions!$C$29)/100) -> 410.87665 | H10: =H9 -> 1.21 | I10: =SUM(B10:H10) -> 6305.6954 | J10: =I10/I9-1 -> 0.024614562
A11: 2031 | B11: =B10*EXP(LN(1+Assumptions!$F$6*IF($A11<=2029,1,Assumptions!$C$26)/100)+IF($A11=2026,Assumptions!$C$20*LN(1+Assumptions!$F$13/100),IF(OR($A11=2027,$A11=2028),(Assumptions!$D$20-Assumptions!$C$20)*LN(1+Assumptions!$F$13/100)/2,0))) -> 2646.9306 | C11: =C10*EXP(LN(1+Assumptions!$F$7*IF($A11<=2029,1,Assumptions!$C$26)/100)+IF($A11=2026,Assumptions!$C$21*LN(1+Assumptions!$F$14/100),IF(OR($A11=2027,$A11=2028),(Assumptions!$D$21-Assumptions!$C$21)*LN(1+Assumptions!$F$14/100)/2,0))) -> 1922.8314 | D11: =D10*EXP(LN(1+Assumptions!$F$8*IF($A11<=2029,1,Assumptions!$C$26)/100)+IF($A11=2026,Assumptions!$C$22*LN(1+Assumptions!$F$15/100),IF(OR($A11=2027,$A11=2028),(Assumptions!$D$22-Assumptions!$C$22)*LN(1+Assumptions!$F$15/100)/2,0))) -> 685.38044 | E11: =E10*EXP(LN(1+Assumptions!$F$9*IF($A11<=2029,1,Assumptions!$C$26)/100)+IF($A11=2026,Assumptions!$C$23*LN(1+Assumptions!$F$16/100),IF(OR($A11=2027,$A11=2028),(Assumptions!$D$23-Assumptions!$C$23)*LN(1+Assumptions!$F$16/100)/2,0))) -> 778.05749 | F11: =F10*EXP(LN(1+Assumptions!$F$10*IF($A11<=2029,1,Assumptions!$C$26)/100)+IF($A11=2026,Assumptions!$C$24*LN(1+Assumptions!$F$17/100),IF(OR($A11=2027,$A11=2028),(Assumptions!$D$24-Assumptions!$C$24)*LN(1+Assumptions!$F$17/100)/2,0))) -> 31.005156 | G11: =G10*(1+IF($A11<=2027,Assumptions!$C$28,Assumptions!$C$29)/100) -> 397.76968 | H11: =H10 -> 1.21 | I11: =SUM(B11:H11) -> 6463.1848 | J11: =I11/I10-1 -> 0.024975742
A12: 2032 | B12: =B11*EXP(LN(1+Assumptions!$F$6*IF($A12<=2029,1,Assumptions!$C$26)/100)+IF($A12=2026,Assumptions!$C$20*LN(1+Assumptions!$F$13/100),IF(OR($A12=2027,$A12=2028),(Assumptions!$D$20-Assumptions!$C$20)*LN(1+Assumptions!$F$13/100)/2,0))) -> 2721.4682 | C12: =C11*EXP(LN(1+Assumptions!$F$7*IF($A12<=2029,1,Assumptions!$C$26)/100)+IF($A12=2026,Assumptions!$C$21*LN(1+Assumptions!$F$14/100),IF(OR($A12=2027,$A12=2028),(Assumptions!$D$21-Assumptions!$C$21)*LN(1+Assumptions!$F$14/100)/2,0))) -> 1974.3633 | D12: =D11*EXP(LN(1+Assumptions!$F$8*IF($A12<=2029,1,Assumptions!$C$26)/100)+IF($A12=2026,Assumptions!$C$22*LN(1+Assumptions!$F$15/100),IF(OR($A12=2027,$A12=2028),(Assumptions!$D$22-Assumptions!$C$22)*LN(1+Assumptions!$F$15/100)/2,0))) -> 725.18734 | E12: =E11*EXP(LN(1+Assumptions!$F$9*IF($A12<=2029,1,Assumptions!$C$26)/100)+IF($A12=2026,Assumptions!$C$23*LN(1+Assumptions!$F$16/100),IF(OR($A12=2027,$A12=2028),(Assumptions!$D$23-Assumptions!$C$23)*LN(1+Assumptions!$F$16/100)/2,0))) -> 789.69723 | F12: =F11*EXP(LN(1+Assumptions!$F$10*IF($A12<=2029,1,Assumptions!$C$26)/100)+IF($A12=2026,Assumptions!$C$24*LN(1+Assumptions!$F$17/100),IF(OR($A12=2027,$A12=2028),(Assumptions!$D$24-Assumptions!$C$24)*LN(1+Assumptions!$F$17/100)/2,0))) -> 29.871608 | G12: =G11*(1+IF($A12<=2027,Assumptions!$C$28,Assumptions!$C$29)/100) -> 385.08083 | H12: =H11 -> 1.21 | I12: =SUM(B12:H12) -> 6626.8785 | J12: =I12/I11-1 -> 0.025327093
A13: 2033 | B13: =B12*EXP(LN(1+Assumptions!$F$6*IF($A13<=2029,1,Assumptions!$C$26)/100)+IF($A13=2026,Assumptions!$C$20*LN(1+Assumptions!$F$13/100),IF(OR($A13=2027,$A13=2028),(Assumptions!$D$20-Assumptions!$C$20)*LN(1+Assumptions!$F$13/100)/2,0))) -> 2798.1048 | C13: =C12*EXP(LN(1+Assumptions!$F$7*IF($A13<=2029,1,Assumptions!$C$26)/100)+IF($A13=2026,Assumptions!$C$21*LN(1+Assumptions!$F$14/100),IF(OR($A13=2027,$A13=2028),(Assumptions!$D$21-Assumptions!$C$21)*LN(1+Assumptions!$F$14/100)/2,0))) -> 2027.2762 | D13: =D12*EXP(LN(1+Assumptions!$F$8*IF($A13<=2029,1,Assumptions!$C$26)/100)+IF($A13=2026,Assumptions!$C$22*LN(1+Assumptions!$F$15/100),IF(OR($A13=2027,$A13=2028),(Assumptions!$D$22-Assumptions!$C$22)*LN(1+Assumptions!$F$15/100)/2,0))) -> 767.30622 | E13: =E12*EXP(LN(1+Assumptions!$F$9*IF($A13<=2029,1,Assumptions!$C$26)/100)+IF($A13=2026,Assumptions!$C$23*LN(1+Assumptions!$F$16/100),IF(OR($A13=2027,$A13=2028),(Assumptions!$D$23-Assumptions!$C$23)*LN(1+Assumptions!$F$16/100)/2,0))) -> 801.5111 | F13: =F12*EXP(LN(1+Assumptions!$F$10*IF($A13<=2029,1,Assumptions!$C$26)/100)+IF($A13=2026,Assumptions!$C$24*LN(1+Assumptions!$F$17/100),IF(OR($A13=2027,$A13=2028),(Assumptions!$D$24-Assumptions!$C$24)*LN(1+Assumptions!$F$17/100)/2,0))) -> 28.779502 | G13: =G12*(1+IF($A13<=2027,Assumptions!$C$28,Assumptions!$C$29)/100) -> 372.79675 | H13: =H12 -> 1.21 | I13: =SUM(B13:H13) -> 6796.9845 | J13: =I13/I12-1 -> 0.025669106
A14: 2034 | B14: =B13*EXP(LN(1+Assumptions!$F$6*IF($A14<=2029,1,Assumptions!$C$26)/100)+IF($A14=2026,Assumptions!$C$20*LN(1+Assumptions!$F$13/100),IF(OR($A14=2027,$A14=2028),(Assumptions!$D$20-Assumptions!$C$20)*LN(1+Assumptions!$F$13/100)/2,0))) -> 2876.8994 | C14: =C13*EXP(LN(1+Assumptions!$F$7*IF($A14<=2029,1,Assumptions!$C$26)/100)+IF($A14=2026,Assumptions!$C$21*LN(1+Assumptions!$F$14/100),IF(OR($A14=2027,$A14=2028),(Assumptions!$D$21-Assumptions!$C$21)*LN(1+Assumptions!$F$14/100)/2,0))) -> 2081.6072 | D14: =D13*EXP(LN(1+Assumptions!$F$8*IF($A14<=2029,1,Assumptions!$C$26)/100)+IF($A14=2026,Assumptions!$C$22*LN(1+Assumptions!$F$15/100),IF(OR($A14=2027,$A14=2028),(Assumptions!$D$22-Assumptions!$C$22)*LN(1+Assumptions!$F$15/100)/2,0))) -> 811.87136 | E14: =E13*EXP(LN(1+Assumptions!$F$9*IF($A14<=2029,1,Assumptions!$C$26)/100)+IF($A14=2026,Assumptions!$C$23*LN(1+Assumptions!$F$16/100),IF(OR($A14=2027,$A14=2028),(Assumptions!$D$23-Assumptions!$C$23)*LN(1+Assumptions!$F$16/100)/2,0))) -> 813.50171 | F14: =F13*EXP(LN(1+Assumptions!$F$10*IF($A14<=2029,1,Assumptions!$C$26)/100)+IF($A14=2026,Assumptions!$C$24*LN(1+Assumptions!$F$17/100),IF(OR($A14=2027,$A14=2028),(Assumptions!$D$24-Assumptions!$C$24)*LN(1+Assumptions!$F$17/100)/2,0))) -> 27.727323 | G14: =G13*(1+IF($A14<=2027,Assumptions!$C$28,Assumptions!$C$29)/100) -> 360.90454 | H14: =H13 -> 1.21 | I14: =SUM(B14:H14) -> 6973.7215 | J14: =I14/I13-1 -> 0.026002264
A15: 2035 | B15: =B14*EXP(LN(1+Assumptions!$F$6*IF($A15<=2029,1,Assumptions!$C$26)/100)+IF($A15=2026,Assumptions!$C$20*LN(1+Assumptions!$F$13/100),IF(OR($A15=2027,$A15=2028),(Assumptions!$D$20-Assumptions!$C$20)*LN(1+Assumptions!$F$13/100)/2,0))) -> 2957.9129 | C15: =C14*EXP(LN(1+Assumptions!$F$7*IF($A15<=2029,1,Assumptions!$C$26)/100)+IF($A15=2026,Assumptions!$C$21*LN(1+Assumptions!$F$14/100),IF(OR($A15=2027,$A15=2028),(Assumptions!$D$21-Assumptions!$C$21)*LN(1+Assumptions!$F$14/100)/2,0))) -> 2137.3943 | D15: =D14*EXP(LN(1+Assumptions!$F$8*IF($A15<=2029,1,Assumptions!$C$26)/100)+IF($A15=2026,Assumptions!$C$22*LN(1+Assumptions!$F$15/100),IF(OR($A15=2027,$A15=2028),(Assumptions!$D$22-Assumptions!$C$22)*LN(1+Assumptions!$F$15/100)/2,0))) -> 859.02485 | E15: =E14*EXP(LN(1+Assumptions!$F$9*IF($A15<=2029,1,Assumptions!$C$26)/100)+IF($A15=2026,Assumptions!$C$23*LN(1+Assumptions!$F$16/100),IF(OR($A15=2027,$A15=2028),(Assumptions!$D$23-Assumptions!$C$23)*LN(1+Assumptions!$F$16/100)/2,0))) -> 825.67169 | F15: =F14*EXP(LN(1+Assumptions!$F$10*IF($A15<=2029,1,Assumptions!$C$26)/100)+IF($A15=2026,Assumptions!$C$24*LN(1+Assumptions!$F$17/100),IF(OR($A15=2027,$A15=2028),(Assumptions!$D$24-Assumptions!$C$24)*LN(1+Assumptions!$F$17/100)/2,0))) -> 26.713612 | G15: =G14*(1+IF($A15<=2027,Assumptions!$C$28,Assumptions!$C$29)/100) -> 349.39168 | H15: =H14 -> 1.21 | I15: =SUM(B15:H15) -> 7157.319 | J15: =I15/I14-1 -> 0.026327043
A17: CAGR 2025-35 | I17: =(I15/I5)^(1/10)-1 -> 0.022804354
A19: Check: 2025 total should equal KNBS 5.7 Mt: | I19: =I5 -> 5712.48

Sheet Supply_Security
A1: Supply security: days of cover and storage
A3: Product | B3: 2025 demand (kt) | C3: Daily demand (ML) | D3: Gross licensed capacity (ML) | E3: Days of demand if tanks full | F3: Stock for standard cover (ML) | G3: Reported cover (days) - input
A4: Diesel (AGO) | B4: =Scenarios!B5 -> 2419.12 | C4: =B4*Assumptions!$C$33/365 -> 7.8803953 | D4: 755.04 | E4: =D4/C4 -> 95.812453 | F4: =C4*Assumptions!$C$30 -> 236.41186 | G4: 19
A5: Petrol (PMS) | B5: =Scenarios!C5 -> 1657.48 | C5: =B5*Assumptions!$C$34/365 -> 6.3029724 | D5: 462.6 | E5: =D5/C5 -> 73.393943 | F5: =C5*Assumptions!$C$30 -> 189.08917 | G5: 16
A6: Jet fuel* | B6: =Scenarios!E5 -> 701.34 | C6: =B6*Assumptions!$C$35/365 -> 2.4423207 | D6: 231.84 | E6: =D6/C6 -> 94.926109 | F6: =C6*Assumptions!$C$30 -> 73.26962 | G6: 49
A9: Product | B9: Reported cover (days) | C9: Shortfall vs standard (days) | D9: Shortfall (ML) | E9: Status (author thresholds)
A10: Diesel (AGO) | B10: =G4 -> 19 | C10: =MAX(Assumptions!$C$30-B10,0) -> 11 | D10: =C10*C4 -> 86.684348 | E10: =IF(B10>=Assumptions!$C$30,"GREEN",IF(B10>=15,"AMBER","RED")) -> AMBER
A11: Petrol (PMS) | B11: =G5 -> 16 | C11: =MAX(Assumptions!$C$30-B11,0) -> 14 | D11: =C11*C5 -> 88.241614 | E11: =IF(B11>=Assumptions!$C$30,"GREEN",IF(B11>=15,"AMBER","RED")) -> AMBER
A12: Jet fuel* | B12: =G6 -> 49 | C12: =MAX(Assumptions!$C$30-B12,0) -> 0 | D12: =C12*C6 -> 0 | E12: =IF(B12>=Assumptions!$C$30,"GREEN",IF(B12>=15,"AMBER","RED")) -> GREEN
A14: Thresholds: GREEN >= standard (30 d); AMBER 15-29; RED < 15. Author framework, not official. Reported cover inputs are from press reports of Ministry/Treasury statements (Apr-2026): petrol 16, diesel 19, jet 49.
A16: Inventory value of cover (USD m) at Aug-2026 landed cost
A17: Landed cost petrol (USD/m3) | B17: 874.26
A18: Landed cost diesel (USD/m3) | B18: 957.05
A19: Days of cover to value | B19: 90
A20: Inventory value (USD m) | B20: =B19*(C5*B17+C4*B18)/1000 -> 1174.7132
A21: Inventory value (KSh bn) | B21: =B20*Assumptions!$C$27/1000 -> 151.77295
A22: Annual carrying cost at financing rate (USD m) | B22: =B20*C22 -> 117.47132 | C22: 0.1

Sheet LPG_Storage
A1: LPG storage requirement (PDP method: planned supply = demand x (1+cover/365); storage = supply / 12)
A3: Year | B3: LPG demand (kt) | C3: Required storage (kt) | D3: Installed + new (kt) | E3: Headroom (kt)
A4: 2025 | B4: =Scenarios!D5 -> 475.95 | C4: =B4*(1+Assumptions!$C$30/365)/12 -> 42.922432 | D4: =Assumptions!$C$31+Assumptions!$C$32 -> 44.43 | E4: =D4-C4 -> 1.5075685
A5: 2026 | B5: =Scenarios!D6 -> 503.25746 | C5: =B5*(1+Assumptions!$C$30/365)/12 -> 45.385091 | D5: =Assumptions!$C$31+Assumptions!$C$32 -> 44.43 | E5: =D5-C5 -> -0.95509054
A6: 2027 | B6: =Scenarios!D7 -> 535.94912 | C6: =B6*(1+Assumptions!$C$30/365)/12 -> 48.333311 | D6: =Assumptions!$C$31+Assumptions!$C$32 -> 44.43 | E6: =D6-C6 -> -3.9033111
A7: 2028 | B7: =Scenarios!D8 -> 570.76443 | C7: =B7*(1+Assumptions!$C$30/365)/12 -> 51.473048 | D7: =Assumptions!$C$31+Assumptions!$C$32 -> 44.43 | E7: =D7-C7 -> -7.0430483
A8: 2029 | B8: =Scenarios!D9 -> 612.20193 | C8: =B8*(1+Assumptions!$C$30/365)/12 -> 55.209992 | D8: =Assumptions!$C$31+Assumptions!$C$32 -> 44.43 | E8: =D8-C8 -> -10.779992
A9: 2030 | B9: =Scenarios!D10 -> 647.75862 | C9: =B9*(1+Assumptions!$C$30/365)/12 -> 58.416588 | D9: =Assumptions!$C$31+Assumptions!$C$32 -> 44.43 | E9: =D9-C9 -> -13.986588
A10: 2031 | B10: =Scenarios!D11 -> 685.38044 | C10: =B10*(1+Assumptions!$C$30/365)/12 -> 61.809423 | D10: =Assumptions!$C$31+Assumptions!$C$32 -> 44.43 | E10: =D10-C10 -> -17.379423
A11: 2032 | B11: =Scenarios!D12 -> 725.18734 | C11: =B11*(1+Assumptions!$C$30/365)/12 -> 65.399315 | D11: =Assumptions!$C$31+Assumptions!$C$32 -> 44.43 | E11: =D11-C11 -> -20.969315
A12: 2033 | B12: =Scenarios!D13 -> 767.30622 | C12: =B12*(1+Assumptions!$C$30/365)/12 -> 69.197707 | D12: =Assumptions!$C$31+Assumptions!$C$32 -> 44.43 | E12: =D12-C12 -> -24.767707
A13: 2034 | B13: =Scenarios!D14 -> 811.87136 | C13: =B13*(1+Assumptions!$C$30/365)/12 -> 73.21671 | D13: =Assumptions!$C$31+Assumptions!$C$32 -> 44.43 | E13: =D13-C13 -> -28.78671
A14: 2035 | B14: =Scenarios!D15 -> 859.02485 | C14: =B14*(1+Assumptions!$C$30/365)/12 -> 77.469136 | D14: =Assumptions!$C$31+Assumptions!$C$32 -> 44.43 | E14: =D14-C14 -> -33.039136

Sheet Project_Economics
A1: South Lokichar - ILLUSTRATIVE scenario model (assumptions are the author's; not official project economics)
A3: Brent, US$/bbl (real, flat) | B3: 70
A4: Differential to Brent, US$/bbl | B4: 6
A5: Plateau production, kbpd | B5: 60
A6: Capex, US$ m | B6: 6000
A7: Opex, US$/bbl | B7: 12
A8: Transport tariff, US$/bbl | B8: 9
A9: Discount rate | B9: 0.1
A10: Royalty, % of revenue | B10: 0.1
A11: Cost-recovery cap, % of net revenue | B11: 0.6
A12: Government share of profit oil | B12: 0.5
A13: Annual decline after plateau | B13: 0.1
A14: Recoverable reserves, mmbbl | B14: 560
A15: Abandonment, % of capex | B15: 0.03
A17: Ramp (share of plateau): 2026 0% / 2027 33% / 2028 66%; plateau to 2037; capex phasing 15/35/30/20% in 2026-29
A19: Year | B19: Ramp / phase | C19: kbpd (raw) | D19: kbpd (eff.) | E19: mmbbl | F19: Cum. mmbbl | G19: Revenue | H19: Royalty | I19: Opex+tariff | J19: Capex | K19: Pre-fiscal CF | L19: Cost pool | M19: Cost recovered | N19: Profit oil | O19: Govt take | P19: Contractor CF | Q19: Disc. factor
A20: 2026 | B20: 0 | C20: =$B$5*B20 -> 0 | D20: =IF(E20>0,C20,0) -> 0 | E20: =IF(AND(A20>2037,C20*365/1000*($B$3-$B$4)<C20*365/1000*($B$7+$B$8)),0,MIN(C20*365/1000,MAX($B$14-0,0))) -> 0 | F20: =0+E20 -> 0 | G20: =E20*($B$3-$B$4) -> 0 | H20: =G20*$B$10 -> 0 | I20: =E20*($B$7+$B$8) -> 0 | J20: =$B$6*0.15+IF(AND(0>0,E20=0),$B$15*$B$6,0) -> 900 | K20: =G20-I20-J20 -> -900 | L20: =0+I20+J20-M20 -> 900 | M20: =MIN(0+I20+J20,$B$11*(G20-H20)) -> 0 | N20: =MAX(G20-H20-M20,0) -> 0 | O20: =H20+N20*$B$12 -> 0 | P20: =G20-H20-N20*$B$12-I20-J20 -> -900 | Q20: =(1+$B$9)^-(A20-2026) -> 1
A21: 2027 | B21: 0.33 | C21: =$B$5*B21 -> 19.8 | D21: =IF(E21>0,C21,0) -> 19.8 | E21: =IF(AND(A21>2037,C21*365/1000*($B$3-$B$4)<C21*365/1000*($B$7+$B$8)),0,MIN(C21*365/1000,MAX($B$14-F20,0))) -> 7.227 | F21: =F20+E21 -> 7.227 | G21: =E21*($B$3-$B$4) -> 462.528 | H21: =G21*$B$10 -> 46.2528 | I21: =E21*($B$7+$B$8) -> 151.767 | J21: =$B$6*0.35+IF(AND(E20>0,E21=0),$B$15*$B$6,0) -> 2100 | K21: =G21-I21-J21 -> -1789.239 | L21: =L20+I21+J21-M21 -> 2902.0019 | M21: =MIN(L20+I21+J21,$B$11*(G21-H21)) -> 249.76512 | N21: =MAX(G21-H21-M21,0) -> 166.51008 | O21: =H21+N21*$B$12 -> 129.50784 | P21: =G21-H21-N21*$B$12-I21-J21 -> -1918.7468 | Q21: =(1+$B$9)^-(A21-2026) -> 0.90909091
A22: 2028 | B22: 0.66 | C22: =$B$5*B22 -> 39.6 | D22: =IF(E22>0,C22,0) -> 39.6 | E22: =IF(AND(A22>2037,C22*365/1000*($B$3-$B$4)<C22*365/1000*($B$7+$B$8)),0,MIN(C22*365/1000,MAX($B$14-F21,0))) -> 14.454 | F22: =F21+E22 -> 21.681 | G22: =E22*($B$3-$B$4) -> 925.056 | H22: =G22*$B$10 -> 92.5056 | I22: =E22*($B$7+$B$8) -> 303.534 | J22: =$B$6*0.3+IF(AND(E21>0,E22=0),$B$15*$B$6,0) -> 1800 | K22: =G22-I22-J22 -> -1178.478 | L22: =L21+I22+J22-M22 -> 4506.0056 | M22: =MIN(L21+I22+J22,$B$11*(G22-H22)) -> 499.53024 | N22: =MAX(G22-H22-M22,0) -> 333.02016 | O22: =H22+N22*$B$12 -> 259.01568 | P22: =G22-H22-N22*$B$12-I22-J22 -> -1437.4937 | Q22: =(1+$B$9)^-(A22-2026) -> 0.82644628
A23: 2029 | B23: 1 | C23: =$B$5*B23 -> 60 | D23: =IF(E23>0,C23,0) -> 60 | E23: =IF(AND(A23>2037,C23*365/1000*($B$3-$B$4)<C23*365/1000*($B$7+$B$8)),0,MIN(C23*365/1000,MAX($B$14-F22,0))) -> 21.9 | F23: =F22+E23 -> 43.581 | G23: =E23*($B$3-$B$4) -> 1401.6 | H23: =G23*$B$10 -> 140.16 | I23: =E23*($B$7+$B$8) -> 459.9 | J23: =$B$6*0.2+IF(AND(E22>0,E23=0),$B$15*$B$6,0) -> 1200 | K23: =G23-I23-J23 -> -258.3 | L23: =L22+I23+J23-M23 -> 5409.0416 | M23: =MIN(L22+I23+J23,$B$11*(G23-H23)) -> 756.864 | N23: =MAX(G23-H23-M23,0) -> 504.576 | O23: =H23+N23*$B$12 -> 392.448 | P23: =G23-H23-N23*$B$12-I23-J23 -> -650.748 | Q23: =(1+$B$9)^-(A23-2026) -> 0.7513148
A24: 2030 | B24: 1 | C24: =$B$5*B24 -> 60 | D24: =IF(E24>0,C24,0) -> 60 | E24: =IF(AND(A24>2037,C24*365/1000*($B$3-$B$4)<C24*365/1000*($B$7+$B$8)),0,MIN(C24*365/1000,MAX($B$14-F23,0))) -> 21.9 | F24: =F23+E24 -> 65.481 | G24: =E24*($B$3-$B$4) -> 1401.6 | H24: =G24*$B$10 -> 140.16 | I24: =E24*($B$7+$B$8) -> 459.9 | J24: =$B$6*0+IF(AND(E23>0,E24=0),$B$15*$B$6,0) -> 0 | K24: =G24-I24-J24 -> 941.7 | L24: =L23+I24+J24-M24 -> 5112.0776 | M24: =MIN(L23+I24+J24,$B$11*(G24-H24)) -> 756.864 | N24: =MAX(G24-H24-M24,0) -> 504.576 | O24: =H24+N24*$B$12 -> 392.448 | P24: =G24-H24-N24*$B$12-I24-J24 -> 549.252 | Q24: =(1+$B$9)^-(A24-2026) -> 0.68301346
A25: 2031 | B25: 1 | C25: =$B$5*B25 -> 60 | D25: =IF(E25>0,C25,0) -> 60 | E25: =IF(AND(A25>2037,C25*365/1000*($B$3-$B$4)<C25*365/1000*($B$7+$B$8)),0,MIN(C25*365/1000,MAX($B$14-F24,0))) -> 21.9 | F25: =F24+E25 -> 87.381 | G25: =E25*($B$3-$B$4) -> 1401.6 | H25: =G25*$B$10 -> 140.16 | I25: =E25*($B$7+$B$8) -> 459.9 | J25: =$B$6*0+IF(AND(E24>0,E25=0),$B$15*$B$6,0) -> 0 | K25: =G25-I25-J25 -> 941.7 | L25: =L24+I25+J25-M25 -> 4815.1136 | M25: =MIN(L24+I25+J25,$B$11*(G25-H25)) -> 756.864 | N25: =MAX(G25-H25-M25,0) -> 504.576 | O25: =H25+N25*$B$12 -> 392.448 | P25: =G25-H25-N25*$B$12-I25-J25 -> 549.252 | Q25: =(1+$B$9)^-(A25-2026) -> 0.62092132
A26: 2032 | B26: 1 | C26: =$B$5*B26 -> 60 | D26: =IF(E26>0,C26,0) -> 60 | E26: =IF(AND(A26>2037,C26*365/1000*($B$3-$B$4)<C26*365/1000*($B$7+$B$8)),0,MIN(C26*365/1000,MAX($B$14-F25,0))) -> 21.9 | F26: =F25+E26 -> 109.281 | G26: =E26*($B$3-$B$4) -> 1401.6 | H26: =G26*$B$10 -> 140.16 | I26: =E26*($B$7+$B$8) -> 459.9 | J26: =$B$6*0+IF(AND(E25>0,E26=0),$B$15*$B$6,0) -> 0 | K26: =G26-I26-J26 -> 941.7 | L26: =L25+I26+J26-M26 -> 4518.1496 | M26: =MIN(L25+I26+J26,$B$11*(G26-H26)) -> 756.864 | N26: =MAX(G26-H26-M26,0) -> 504.576 | O26: =H26+N26*$B$12 -> 392.448 | P26: =G26-H26-N26*$B$12-I26-J26 -> 549.252 | Q26: =(1+$B$9)^-(A26-2026) -> 0.56447393
A27: 2033 | B27: 1 | C27: =$B$5*B27 -> 60 | D27: =IF(E27>0,C27,0) -> 60 | E27: =IF(AND(A27>2037,C27*365/1000*($B$3-$B$4)<C27*365/1000*($B$7+$B$8)),0,MIN(C27*365/1000,MAX($B$14-F26,0))) -> 21.9 | F27: =F26+E27 -> 131.181 | G27: =E27*($B$3-$B$4) -> 1401.6 | H27: =G27*$B$10 -> 140.16 | I27: =E27*($B$7+$B$8) -> 459.9 | J27: =$B$6*0+IF(AND(E26>0,E27=0),$B$15*$B$6,0) -> 0 | K27: =G27-I27-J27 -> 941.7 | L27: =L26+I27+J27-M27 -> 4221.1856 | M27: =MIN(L26+I27+J27,$B$11*(G27-H27)) -> 756.864 | N27: =MAX(G27-H27-M27,0) -> 504.576 | O27: =H27+N27*$B$12 -> 392.448 | P27: =G27-H27-N27*$B$12-I27-J27 -> 549.252 | Q27: =(1+$B$9)^-(A27-2026) -> 0.51315812
A28: 2034 | B28: 1 | C28: =$B$5*B28 -> 60 | D28: =IF(E28>0,C28,0) -> 60 | E28: =IF(AND(A28>2037,C28*365/1000*($B$3-$B$4)<C28*365/1000*($B$7+$B$8)),0,MIN(C28*365/1000,MAX($B$14-F27,0))) -> 21.9 | F28: =F27+E28 -> 153.081 | G28: =E28*($B$3-$B$4) -> 1401.6 | H28: =G28*$B$10 -> 140.16 | I28: =E28*($B$7+$B$8) -> 459.9 | J28: =$B$6*0+IF(AND(E27>0,E28=0),$B$15*$B$6,0) -> 0 | K28: =G28-I28-J28 -> 941.7 | L28: =L27+I28+J28-M28 -> 3924.2216 | M28: =MIN(L27+I28+J28,$B$11*(G28-H28)) -> 756.864 | N28: =MAX(G28-H28-M28,0) -> 504.576 | O28: =H28+N28*$B$12 -> 392.448 | P28: =G28-H28-N28*$B$12-I28-J28 -> 549.252 | Q28: =(1+$B$9)^-(A28-2026) -> 0.46650738
A29: 2035 | B29: 1 | C29: =$B$5*B29 -> 60 | D29: =IF(E29>0,C29,0) -> 60 | E29: =IF(AND(A29>2037,C29*365/1000*($B$3-$B$4)<C29*365/1000*($B$7+$B$8)),0,MIN(C29*365/1000,MAX($B$14-F28,0))) -> 21.9 | F29: =F28+E29 -> 174.981 | G29: =E29*($B$3-$B$4) -> 1401.6 | H29: =G29*$B$10 -> 140.16 | I29: =E29*($B$7+$B$8) -> 459.9 | J29: =$B$6*0+IF(AND(E28>0,E29=0),$B$15*$B$6,0) -> 0 | K29: =G29-I29-J29 -> 941.7 | L29: =L28+I29+J29-M29 -> 3627.2576 | M29: =MIN(L28+I29+J29,$B$11*(G29-H29)) -> 756.864 | N29: =MAX(G29-H29-M29,0) -> 504.576 | O29: =H29+N29*$B$12 -> 392.448 | P29: =G29-H29-N29*$B$12-I29-J29 -> 549.252 | Q29: =(1+$B$9)^-(A29-2026) -> 0.42409762
A30: 2036 | B30: 1 | C30: =$B$5*B30 -> 60 | D30: =IF(E30>0,C30,0) -> 60 | E30: =IF(AND(A30>2037,C30*365/1000*($B$3-$B$4)<C30*365/1000*($B$7+$B$8)),0,MIN(C30*365/1000,MAX($B$14-F29,0))) -> 21.9 | F30: =F29+E30 -> 196.881 | G30: =E30*($B$3-$B$4) -> 1401.6 | H30: =G30*$B$10 -> 140.16 | I30: =E30*($B$7+$B$8) -> 459.9 | J30: =$B$6*0+IF(AND(E29>0,E30=0),$B$15*$B$6,0) -> 0 | K30: =G30-I30-J30 -> 941.7 | L30: =L29+I30+J30-M30 -> 3330.2936 | M30: =MIN(L29+I30+J30,$B$11*(G30-H30)) -> 756.864 | N30: =MAX(G30-H30-M30,0) -> 504.576 | O30: =H30+N30*$B$12 -> 392.448 | P30: =G30-H30-N30*$B$12-I30-J30 -> 549.252 | Q30: =(1+$B$9)^-(A30-2026) -> 0.38554329
A31: 2037 | B31: 1 | C31: =$B$5*B31 -> 60 | D31: =IF(E31>0,C31,0) -> 60 | E31: =IF(AND(A31>2037,C31*365/1000*($B$3-$B$4)<C31*365/1000*($B$7+$B$8)),0,MIN(C31*365/1000,MAX($B$14-F30,0))) -> 21.9 | F31: =F30+E31 -> 218.781 | G31: =E31*($B$3-$B$4) -> 1401.6 | H31: =G31*$B$10 -> 140.16 | I31: =E31*($B$7+$B$8) -> 459.9 | J31: =$B$6*0+IF(AND(E30>0,E31=0),$B$15*$B$6,0) -> 0 | K31: =G31-I31-J31 -> 941.7 | L31: =L30+I31+J31-M31 -> 3033.3296 | M31: =MIN(L30+I31+J31,$B$11*(G31-H31)) -> 756.864 | N31: =MAX(G31-H31-M31,0) -> 504.576 | O31: =H31+N31*$B$12 -> 392.448 | P31: =G31-H31-N31*$B$12-I31-J31 -> 549.252 | Q31: =(1+$B$9)^-(A31-2026) -> 0.3504939
A32: 2038 | C32: =D31*(1-$B$13) -> 54 | D32: =IF(E32>0,C32,0) -> 54 | E32: =IF(AND(A32>2037,C32*365/1000*($B$3-$B$4)<C32*365/1000*($B$7+$B$8)),0,MIN(C32*365/1000,MAX($B$14-F31,0))) -> 19.71 | F32: =F31+E32 -> 238.491 | G32: =E32*($B$3-$B$4) -> 1261.44 | H32: =G32*$B$10 -> 126.144 | I32: =E32*($B$7+$B$8) -> 413.91 | J32: =$B$6*0+IF(AND(E31>0,E32=0),$B$15*$B$6,0) -> 0 | K32: =G32-I32-J32 -> 847.53 | L32: =L31+I32+J32-M32 -> 2766.062 | M32: =MIN(L31+I32+J32,$B$11*(G32-H32)) -> 681.1776 | N32: =MAX(G32-H32-M32,0) -> 454.1184 | O32: =H32+N32*$B$12 -> 353.2032 | P32: =G32-H32-N32*$B$12-I32-J32 -> 494.3268 | Q32: =(1+$B$9)^-(A32-2026) -> 0.31863082
A33: 2039 | C33: =D32*(1-$B$13) -> 48.6 | D33: =IF(E33>0,C33,0) -> 48.6 | E33: =IF(AND(A33>2037,C33*365/1000*($B$3-$B$4)<C33*365/1000*($B$7+$B$8)),0,MIN(C33*365/1000,MAX($B$14-F32,0))) -> 17.739 | F33: =F32+E33 -> 256.23 | G33: =E33*($B$3-$B$4) -> 1135.296 | H33: =G33*$B$10 -> 113.5296 | I33: =E33*($B$7+$B$8) -> 372.519 | J33: =$B$6*0+IF(AND(E32>0,E33=0),$B$15*$B$6,0) -> 0 | K33: =G33-I33-J33 -> 762.777 | L33: =L32+I33+J33-M33 -> 2525.5212 | M33: =MIN(L32+I33+J33,$B$11*(G33-H33)) -> 613.05984 | N33: =MAX(G33-H33-M33,0) -> 408.70656 | O33: =H33+N33*$B$12 -> 317.88288 | P33: =G33-H33-N33*$B$12-I33-J33 -> 444.89412 | Q33: =(1+$B$9)^-(A33-2026) -> 0.28966438
A34: 2040 | C34: =D33*(1-$B$13) -> 43.74 | D34: =IF(E34>0,C34,0) -> 43.74 | E34: =IF(AND(A34>2037,C34*365/1000*($B$3-$B$4)<C34*365/1000*($B$7+$B$8)),0,MIN(C34*365/1000,MAX($B$14-F33,0))) -> 15.9651 | F34: =F33+E34 -> 272.1951 | G34: =E34*($B$3-$B$4) -> 1021.7664 | H34: =G34*$B$10 -> 102.17664 | I34: =E34*($B$7+$B$8) -> 335.2671 | J34: =$B$6*0+IF(AND(E33>0,E34=0),$B$15*$B$6,0) -> 0 | K34: =G34-I34-J34 -> 686.4993 | L34: =L33+I34+J34-M34 -> 2309.0344 | M34: =MIN(L33+I34+J34,$B$11*(G34-H34)) -> 551.75386 | N34: =MAX(G34-H34-M34,0) -> 367.8359 | O34: =H34+N34*$B$12 -> 286.09459 | P34: =G34-H34-N34*$B$12-I34-J34 -> 400.40471 | Q34: =(1+$B$9)^-(A34-2026) -> 0.26333125
A35: 2041 | C35: =D34*(1-$B$13) -> 39.366 | D35: =IF(E35>0,C35,0) -> 39.366 | E35: =IF(AND(A35>2037,C35*365/1000*($B$3-$B$4)<C35*365/1000*($B$7+$B$8)),0,MIN(C35*365/1000,MAX($B$14-F34,0))) -> 14.36859 | F35: =F34+E35 -> 286.56369 | G35: =E35*($B$3-$B$4) -> 919.58976 | H35: =G35*$B$10 -> 91.958976 | I35: =E35*($B$7+$B$8) -> 301.74039 | J35: =$B$6*0+IF(AND(E34>0,E35=0),$B$15*$B$6,0) -> 0 | K35: =G35-I35-J35 -> 617.84937 | L35: =L34+I35+J35-M35 -> 2114.1964 | M35: =MIN(L34+I35+J35,$B$11*(G35-H35)) -> 496.57847 | N35: =MAX(G35-H35-M35,0) -> 331.05231 | O35: =H35+N35*$B$12 -> 257.48513 | P35: =G35-H35-N35*$B$12-I35-J35 -> 360.36424 | Q35: =(1+$B$9)^-(A35-2026) -> 0.23939205
A36: 2042 | C36: =D35*(1-$B$13) -> 35.4294 | D36: =IF(E36>0,C36,0) -> 35.4294 | E36: =IF(AND(A36>2037,C36*365/1000*($B$3-$B$4)<C36*365/1000*($B$7+$B$8)),0,MIN(C36*365/1000,MAX($B$14-F35,0))) -> 12.931731 | F36: =F35+E36 -> 299.49542 | G36: =E36*($B$3-$B$4) -> 827.63078 | H36: =G36*$B$10 -> 82.763078 | I36: =E36*($B$7+$B$8) -> 271.56635 | J36: =$B$6*0+IF(AND(E35>0,E36=0),$B$15*$B$6,0) -> 0 | K36: =G36-I36-J36 -> 556.06443 | L36: =L35+I36+J36-M36 -> 1938.8421 | M36: =MIN(L35+I36+J36,$B$11*(G36-H36)) -> 446.92062 | N36: =MAX(G36-H36-M36,0) -> 297.94708 | O36: =H36+N36*$B$12 -> 231.73662 | P36: =G36-H36-N36*$B$12-I36-J36 -> 324.32781 | Q36: =(1+$B$9)^-(A36-2026) -> 0.21762914
A37: 2043 | C37: =D36*(1-$B$13) -> 31.88646 | D37: =IF(E37>0,C37,0) -> 31.88646 | E37: =IF(AND(A37>2037,C37*365/1000*($B$3-$B$4)<C37*365/1000*($B$7+$B$8)),0,MIN(C37*365/1000,MAX($B$14-F36,0))) -> 11.638558 | F37: =F36+E37 -> 311.13398 | G37: =E37*($B$3-$B$4) -> 744.86771 | H37: =G37*$B$10 -> 74.486771 | I37: =E37*($B$7+$B$8) -> 244.40972 | J37: =$B$6*0+IF(AND(E36>0,E37=0),$B$15*$B$6,0) -> 0 | K37: =G37-I37-J37 -> 500.45799 | L37: =L36+I37+J37-M37 -> 1781.0232 | M37: =MIN(L36+I37+J37,$B$11*(G37-H37)) -> 402.22856 | N37: =MAX(G37-H37-M37,0) -> 268.15237 | O37: =H37+N37*$B$12 -> 208.56296 | P37: =G37-H37-N37*$B$12-I37-J37 -> 291.89503 | Q37: =(1+$B$9)^-(A37-2026) -> 0.19784467
A38: 2044 | C38: =D37*(1-$B$13) -> 28.697814 | D38: =IF(E38>0,C38,0) -> 28.697814 | E38: =IF(AND(A38>2037,C38*365/1000*($B$3-$B$4)<C38*365/1000*($B$7+$B$8)),0,MIN(C38*365/1000,MAX($B$14-F37,0))) -> 10.474702 | F38: =F37+E38 -> 321.60868 | G38: =E38*($B$3-$B$4) -> 670.38094 | H38: =G38*$B$10 -> 67.038094 | I38: =E38*($B$7+$B$8) -> 219.96874 | J38: =$B$6*0+IF(AND(E37>0,E38=0),$B$15*$B$6,0) -> 0 | K38: =G38-I38-J38 -> 450.41219 | L38: =L37+I38+J38-M38 -> 1638.9863 | M38: =MIN(L37+I38+J38,$B$11*(G38-H38)) -> 362.0057 | N38: =MAX(G38-H38-M38,0) -> 241.33714 | O38: =H38+N38*$B$12 -> 187.70666 | P38: =G38-H38-N38*$B$12-I38-J38 -> 262.70553 | Q38: =(1+$B$9)^-(A38-2026) -> 0.17985879
A39: 2045 | C39: =D38*(1-$B$13) -> 25.828033 | D39: =IF(E39>0,C39,0) -> 25.828033 | E39: =IF(AND(A39>2037,C39*365/1000*($B$3-$B$4)<C39*365/1000*($B$7+$B$8)),0,MIN(C39*365/1000,MAX($B$14-F38,0))) -> 9.4272319 | F39: =F38+E39 -> 331.03591 | G39: =E39*($B$3-$B$4) -> 603.34284 | H39: =G39*$B$10 -> 60.334284 | I39: =E39*($B$7+$B$8) -> 197.97187 | J39: =$B$6*0+IF(AND(E38>0,E39=0),$B$15*$B$6,0) -> 0 | K39: =G39-I39-J39 -> 405.37097 | L39: =L38+I39+J39-M39 -> 1511.153 | M39: =MIN(L38+I39+J39,$B$11*(G39-H39)) -> 325.80513 | N39: =MAX(G39-H39-M39,0) -> 217.20342 | O39: =H39+N39*$B$12 -> 168.936 | P39: =G39-H39-N39*$B$12-I39-J39 -> 236.43498 | Q39: =(1+$B$9)^-(A39-2026) -> 0.16350799
A40: 2046 | C40: =D39*(1-$B$13) -> 23.245229 | D40: =IF(E40>0,C40,0) -> 23.245229 | E40: =IF(AND(A40>2037,C40*365/1000*($B$3-$B$4)<C40*365/1000*($B$7+$B$8)),0,MIN(C40*365/1000,MAX($B$14-F39,0))) -> 8.4845087 | F40: =F39+E40 -> 339.52042 | G40: =E40*($B$3-$B$4) -> 543.00856 | H40: =G40*$B$10 -> 54.300856 | I40: =E40*($B$7+$B$8) -> 178.17468 | J40: =$B$6*0+IF(AND(E39>0,E40=0),$B$15*$B$6,0) -> 0 | K40: =G40-I40-J40 -> 364.83387 | L40: =L39+I40+J40-M40 -> 1396.1031 | M40: =MIN(L39+I40+J40,$B$11*(G40-H40)) -> 293.22462 | N40: =MAX(G40-H40-M40,0) -> 195.48308 | O40: =H40+N40*$B$12 -> 152.0424 | P40: =G40-H40-N40*$B$12-I40-J40 -> 212.79148 | Q40: =(1+$B$9)^-(A40-2026) -> 0.14864363
A41: 2047 | C41: =D40*(1-$B$13) -> 20.920706 | D41: =IF(E41>0,C41,0) -> 20.920706 | E41: =IF(AND(A41>2037,C41*365/1000*($B$3-$B$4)<C41*365/1000*($B$7+$B$8)),0,MIN(C41*365/1000,MAX($B$14-F40,0))) -> 7.6360578 | F41: =F40+E41 -> 347.15648 | G41: =E41*($B$3-$B$4) -> 488.7077 | H41: =G41*$B$10 -> 48.87077 | I41: =E41*($B$7+$B$8) -> 160.35721 | J41: =$B$6*0+IF(AND(E40>0,E41=0),$B$15*$B$6,0) -> 0 | K41: =G41-I41-J41 -> 328.35049 | L41: =L40+I41+J41-M41 -> 1292.5581 | M41: =MIN(L40+I41+J41,$B$11*(G41-H41)) -> 263.90216 | N41: =MAX(G41-H41-M41,0) -> 175.93477 | O41: =H41+N41*$B$12 -> 136.83816 | P41: =G41-H41-N41*$B$12-I41-J41 -> 191.51233 | Q41: =(1+$B$9)^-(A41-2026) -> 0.13513057
A42: 2048 | C42: =D41*(1-$B$13) -> 18.828636 | D42: =IF(E42>0,C42,0) -> 18.828636 | E42: =IF(AND(A42>2037,C42*365/1000*($B$3-$B$4)<C42*365/1000*($B$7+$B$8)),0,MIN(C42*365/1000,MAX($B$14-F41,0))) -> 6.8724521 | F42: =F41+E42 -> 354.02893 | G42: =E42*($B$3-$B$4) -> 439.83693 | H42: =G42*$B$10 -> 43.983693 | I42: =E42*($B$7+$B$8) -> 144.32149 | J42: =$B$6*0+IF(AND(E41>0,E42=0),$B$15*$B$6,0) -> 0 | K42: =G42-I42-J42 -> 295.51544 | L42: =L41+I42+J42-M42 -> 1199.3677 | M42: =MIN(L41+I42+J42,$B$11*(G42-H42)) -> 237.51194 | N42: =MAX(G42-H42-M42,0) -> 158.3413 | O42: =H42+N42*$B$12 -> 123.15434 | P42: =G42-H42-N42*$B$12-I42-J42 -> 172.3611 | Q42: =(1+$B$9)^-(A42-2026) -> 0.12284597
A43: 2049 | C43: =D42*(1-$B$13) -> 16.945772 | D43: =IF(E43>0,C43,0) -> 16.945772 | E43: =IF(AND(A43>2037,C43*365/1000*($B$3-$B$4)<C43*365/1000*($B$7+$B$8)),0,MIN(C43*365/1000,MAX($B$14-F42,0))) -> 6.1852068 | F43: =F42+E43 -> 360.21414 | G43: =E43*($B$3-$B$4) -> 395.85324 | H43: =G43*$B$10 -> 39.585324 | I43: =E43*($B$7+$B$8) -> 129.88934 | J43: =$B$6*0+IF(AND(E42>0,E43=0),$B$15*$B$6,0) -> 0 | K43: =G43-I43-J43 -> 265.96389 | L43: =L42+I43+J43-M43 -> 1115.4963 | M43: =MIN(L42+I43+J43,$B$11*(G43-H43)) -> 213.76075 | N43: =MAX(G43-H43-M43,0) -> 142.50717 | O43: =H43+N43*$B$12 -> 110.83891 | P43: =G43-H43-N43*$B$12-I43-J43 -> 155.12499 | Q43: =(1+$B$9)^-(A43-2026) -> 0.11167816
...

Sheet Sensitivity
A1: Static outputs from the Python pipeline (data/clean/*.csv)
A3: Project NPV10, US$ m: Brent \ plateau | B3: 80% of 60 kbpd | C3: 90% of 60 kbpd | D3: 100% of 60 kbpd | E3: 110% of 60 kbpd | F3: 120% of 60 kbpd
A4: US$50 | B4: -2310 | C4: -1949 | D4: -1588 | E4: -1227 | F4: -866
A5: US$60 | B5: -1055 | C5: -537 | D5: -19 | E5: 499 | F5: 1017
A6: US$70 | B6: 201 | C6: 876 | D6: 1551 | E6: 2225 | F6: 2900
A7: US$80 | B7: 1456 | C7: 2288 | D7: 3120 | E7: 3952 | F7: 4784
A8: US$90 | B8: 2712 | C8: 3701 | D8: 4689 | E8: 5678 | F8: 6667
A9: US$100 | B9: 3968 | C9: 5113 | D9: 6259 | E9: 7405 | F9: 8550
A12: Tornado driver | B12: Downside (US$ m) | C12: Upside (US$ m)
A13: Price differential ($10/$2) | B13: -628 | C13: 628
A14: Opex+tariff (+20%/-20%) | B14: -659 | C14: 659
A15: Discount rate (12%/8%) | B15: -741 | C15: 962
A16: CAPEX (+20%/-20%) | B16: -1040 | C16: 1040
A17: Plateau output (-20%/+20% of 60 kbpd) | B17: -1350 | C17: 1350
A18: Oil price (Brent $55-$85) | B18: -2354 | C18: 2354
A21: fiscal_case | B21: brent | C21: NPV_contractor | D21: IRR_contractor | E21: NPV_gov | F21: gov_undisc | G21: gov_share_pct | H21: contractor_breakeven_brent
A22: Fiscal case A (cap 60%, gov profit oil 50%) | B22: 60 | C22: -2392.036 | D22: 0.017 | E22: 2373.058 | F22: 6023.992 | G22: 84.28 | H22: 82.322
A23: Fiscal case A (cap 60%, gov profit oil 50%) | B23: 70 | C23: -1262.008 | D23: 0.058 | E23: 2812.514 | F23: 7139.546 | G23: 64.137 | H23: 82.322
A24: Fiscal case A (cap 60%, gov profit oil 50%) | B24: 80 | C24: -217.896 | D24: 0.093 | E24: 3337.884 | F24: 9032.047 | G24: 59.752 | H24: 82.322
A25: Fiscal case B (cap 80%, gov profit oil 35%) | B25: 60 | C25: -1437.487 | D25: 0.051 | E25: 1418.51 | F25: 3900.087 | G25: 54.565 | H25: 73.135
A26: Fiscal case B (cap 80%, gov profit oil 35%) | B26: 70 | C26: -329.963 | D26: 0.088 | E26: 1880.468 | F26: 5553.497 | G26: 49.889 | H26: 73.135
A27: Fiscal case B (cap 80%, gov profit oil 35%) | B27: 80 | C27: 705.826 | D27: 0.125 | E27: 2414.162 | F27: 7206.908 | G27: 47.678 | H27: 73.135
A30: case | B30: total_2030_kt | C30: total_2035_kt | D30: vs_baseline_2035_%
A31: Baseline | B31: 6305.7 | C31: 7157.3 | D31: 0
A32: Fade 0.6 (slower post-2029) | B32: 6264.4 | C32: 6870.7 | D32: -4
A33: Fade 1.0 (no fade) | B33: 6347 | C33: 7456.1 | D33: 4.2
A34: No 2026 price shock | B34: 6678.5 | C34: 7587.5 | D34: 6
A35: Shock x1.5 | B35: 6150.6 | C35: 6978.3 | D35: -2.5
A36: Elasticities x0.5 | B36: 6488 | C36: 7367.7 | D36: 2.9
A37: Elasticities x2 | B37: 5963.9 | C37: 6762.8 | D37: -5.5
A38: Underlying growth +2 pts/yr (2025 momentum) | B38: 6873.1 | C38: 8410.2 | D38: 17.5
A39: Underlying growth -1 pt/yr | B39: 6037.3 | C39: 6599.1 | D39: -7.8
